{
 "cells": [
  {
   "cell_type": "code",
   "execution_count": 1,
   "id": "183c6f72",
   "metadata": {},
   "outputs": [],
   "source": [
    "import pandas as pd\n",
    "from dash import dcc, html, Dash\n",
    "from dash.dependencies import Input, Output\n",
    "import plotly.express as px"
   ]
  },
  {
   "cell_type": "code",
   "execution_count": 2,
   "id": "295aa623",
   "metadata": {},
   "outputs": [],
   "source": [
    "# Read the airline data into pandas dataframe\n",
    "spacex_df = pd.read_csv(\"spacex.csv\")\n",
    "max_payload = spacex_df['Payload Mass (kg)'].max()\n",
    "min_payload = spacex_df['Payload Mass (kg)'].min()"
   ]
  },
  {
   "cell_type": "code",
   "execution_count": 3,
   "id": "aad4c251",
   "metadata": {},
   "outputs": [
    {
     "data": {
      "text/plain": [
       "['Unnamed: 0',\n",
       " 'Flight Number',\n",
       " 'Date',\n",
       " 'Time (UTC)',\n",
       " 'Booster Version',\n",
       " 'Launch Site',\n",
       " 'Payload',\n",
       " 'Payload Mass (kg)',\n",
       " 'Orbit',\n",
       " 'Customer',\n",
       " 'Landing Outcome',\n",
       " 'class',\n",
       " 'Lat',\n",
       " 'Long']"
      ]
     },
     "execution_count": 3,
     "metadata": {},
     "output_type": "execute_result"
    }
   ],
   "source": [
    "spacex_df.columns.tolist()"
   ]
  },
  {
   "cell_type": "code",
   "execution_count": 4,
   "id": "3078dfcb",
   "metadata": {},
   "outputs": [],
   "source": [
    "# Create a dash application\n",
    "app = Dash(__name__)"
   ]
  },
  {
   "cell_type": "code",
   "execution_count": 5,
   "id": "dc52f655",
   "metadata": {},
   "outputs": [],
   "source": [
    "# Create an app layout\n",
    "app.layout = html.Div(children=[html.H1('SpaceX Launch Records Dashboard', style={'textAlign': 'center', 'color': '#503D36', 'font-size': 40}\n",
    "                                       ),\n",
    "                                \n",
    "                                dcc.Dropdown(id='site-dropdown',options=[{'label': 'All Sites', 'value': 'ALL'},\n",
    "                                                                         {'label': 'Cape Canaveral Launch Complex 40 (CAFS LC-40)', 'value': 'CCAFS LC-40'},\n",
    "                                                                         {'label': 'Cape Canaveral Space Launch Complex 40 (CCAFS SLC-40)', 'value': 'CCAFS SLC-40'},\n",
    "                                                                         {'label': 'Kennedy Space Center Launch Complex 39A (KSC LC-39A)', 'value': 'KSC LC-39A'},\n",
    "                                                                         {'label': 'Vandenberg Air Force Base Space Launch Complex (VAFB SLC-4E)', 'value': 'VAFB SLC-4E'}\n",
    "                                                                        ],\n",
    "                                             value='ALL',\n",
    "                                             placeholder=\"Select a Launch Site\",\n",
    "                                             searchable=True\n",
    "                                            ),\n",
    "                                \n",
    "                                html.Br(),\n",
    "                                \n",
    "                                html.Div(dcc.Graph(id='success-pie-chart')),\n",
    "                                \n",
    "                                html.Br(),\n",
    "                                \n",
    "                                html.P(\"Payload range (Kg):\"),\n",
    "                                \n",
    "                                dcc.RangeSlider(id='payload-slider',\n",
    "                                                min=0, max=10000, step=1000,\n",
    "                                                value=[min_payload, max_payload]),\n",
    "                                \n",
    "                                html.Br(),\n",
    "                                \n",
    "                                html.Div(dcc.Graph(id='success-payload-scatter-chart'))\n",
    "                               ]\n",
    "                     )"
   ]
  },
  {
   "cell_type": "code",
   "execution_count": 6,
   "id": "0be7e92f",
   "metadata": {},
   "outputs": [],
   "source": [
    "@app.callback(Output(component_id='success-pie-chart', component_property='figure'),\n",
    "              Input(component_id='site-dropdown', component_property='value'))\n",
    "\n",
    "def get_pie_chart(entered_site):\n",
    "    filtered_df = spacex_df.groupby(['Launch Site'], as_index=False).mean()\n",
    "    if entered_site == 'ALL':\n",
    "        return px.pie(filtered_df, values='class', names='Launch Site', title='Launch Success Rate For All Sites')\n",
    "    # return the outcomes in pie chart for a selected site\n",
    "    filtered_df = spacex_df[spacex_df['Launch Site'] == entered_site]\n",
    "    filtered_df['outcome'] = filtered_df['class'].apply(lambda x: 'Success' if (x == 1) else 'Failure')\n",
    "    filtered_df['counts'] = 1\n",
    "    return px.pie(filtered_df, values='counts', names='outcome', title='Launch Success Rate For ' + entered_site)"
   ]
  },
  {
   "cell_type": "code",
   "execution_count": 7,
   "id": "7948bb86",
   "metadata": {},
   "outputs": [],
   "source": [
    "@app.callback(Output(component_id='success-payload-scatter-chart', component_property='figure'),\n",
    "              [Input(component_id='site-dropdown', component_property='value'),\n",
    "               Input(component_id=\"payload-slider\", component_property=\"value\")])\n",
    "\n",
    "def get_scatter_chart(entered_site, slider):\n",
    "    filtered_df = spacex_df[\n",
    "        (slider[0] <= spacex_df['Payload Mass (kg)']) & (spacex_df['Payload Mass (kg)'] <= slider[1])\n",
    "    ]\n",
    "    if entered_site == 'ALL':\n",
    "        return px.scatter(filtered_df,\n",
    "                          x='Payload Mass (kg)', y='class',\n",
    "                          color='Booster Version Category',\n",
    "                          title='Launch Success Rate For All Sites')\n",
    "    # return the outcomes in pie chart for a selected site\n",
    "    filtered_df = filtered_df[filtered_df['Launch Site'] == entered_site]\n",
    "    filtered_df['outcome'] = filtered_df['class'].apply(lambda x: 'Success' if (x == 1) else 'Failure')\n",
    "    filtered_df['counts'] = 1\n",
    "    return px.scatter (filtered_df,\n",
    "                       x='Payload Mass (kg)', y='class',\n",
    "                       color='Booster Version Category',\n",
    "                       title='Launch Success Rate For ' + entered_site)"
   ]
  },
  {
   "cell_type": "code",
   "execution_count": null,
   "id": "2f4f6ee1",
   "metadata": {},
   "outputs": [
    {
     "name": "stdout",
     "output_type": "stream",
     "text": [
      "Dash is running on http://127.0.0.1:8050/\n",
      "\n",
      " * Serving Flask app '__main__'\n",
      " * Debug mode: off\n"
     ]
    },
    {
     "name": "stderr",
     "output_type": "stream",
     "text": [
      "WARNING: This is a development server. Do not use it in a production deployment. Use a production WSGI server instead.\n",
      " * Running on http://127.0.0.1:8050\n",
      "Press CTRL+C to quit\n",
      "127.0.0.1 - - [12/May/2023 16:12:17] \"GET / HTTP/1.1\" 200 -\n",
      "127.0.0.1 - - [12/May/2023 16:12:17] \"GET /_dash-layout HTTP/1.1\" 200 -\n",
      "127.0.0.1 - - [12/May/2023 16:12:17] \"GET /_dash-dependencies HTTP/1.1\" 200 -\n",
      "127.0.0.1 - - [12/May/2023 16:12:17] \"GET /_dash-component-suites/dash/dcc/async-dropdown.js HTTP/1.1\" 304 -\n",
      "127.0.0.1 - - [12/May/2023 16:12:17] \"GET /_dash-component-suites/dash/dcc/async-graph.js HTTP/1.1\" 304 -\n",
      "127.0.0.1 - - [12/May/2023 16:12:17] \"GET /_dash-component-suites/dash/dcc/async-plotlyjs.js HTTP/1.1\" 304 -\n",
      "127.0.0.1 - - [12/May/2023 16:12:17] \"GET /_dash-component-suites/dash/dcc/async-slider.js HTTP/1.1\" 304 -\n",
      "[2023-05-12 16:12:17,421] ERROR in app: Exception on /_dash-update-component [POST]\n",
      "Traceback (most recent call last):\n",
      "  File \"C:\\Users\\DELL\\AppData\\Roaming\\Python\\Python39\\site-packages\\flask\\app.py\", line 2528, in wsgi_app\n",
      "    response = self.full_dispatch_request()\n",
      "  File \"C:\\Users\\DELL\\AppData\\Roaming\\Python\\Python39\\site-packages\\flask\\app.py\", line 1825, in full_dispatch_request\n",
      "    rv = self.handle_user_exception(e)\n",
      "  File \"C:\\Users\\DELL\\AppData\\Roaming\\Python\\Python39\\site-packages\\flask\\app.py\", line 1823, in full_dispatch_request\n",
      "    rv = self.dispatch_request()\n",
      "  File \"C:\\Users\\DELL\\AppData\\Roaming\\Python\\Python39\\site-packages\\flask\\app.py\", line 1799, in dispatch_request\n",
      "    return self.ensure_sync(self.view_functions[rule.endpoint])(**view_args)\n",
      "  File \"C:\\ProgramData\\Anaconda3\\lib\\site-packages\\dash\\dash.py\", line 1283, in dispatch\n",
      "    ctx.run(\n",
      "  File \"C:\\ProgramData\\Anaconda3\\lib\\site-packages\\dash\\_callback.py\", line 450, in add_context\n",
      "    output_value = func(*func_args, **func_kwargs)  # %% callback invoked %%\n",
      "  File \"C:\\Users\\DELL\\AppData\\Local\\Temp\\ipykernel_16068\\3660098658.py\", line 10, in get_scatter_chart\n",
      "    return px.scatter(filtered_df,\n",
      "  File \"C:\\ProgramData\\Anaconda3\\lib\\site-packages\\plotly\\express\\_chart_types.py\", line 66, in scatter\n",
      "    return make_figure(args=locals(), constructor=go.Scatter)\n",
      "  File \"C:\\ProgramData\\Anaconda3\\lib\\site-packages\\plotly\\express\\_core.py\", line 1990, in make_figure\n",
      "    args = build_dataframe(args, constructor)\n",
      "  File \"C:\\ProgramData\\Anaconda3\\lib\\site-packages\\plotly\\express\\_core.py\", line 1405, in build_dataframe\n",
      "    df_output, wide_id_vars = process_args_into_dataframe(\n",
      "  File \"C:\\ProgramData\\Anaconda3\\lib\\site-packages\\plotly\\express\\_core.py\", line 1207, in process_args_into_dataframe\n",
      "    raise ValueError(err_msg)\n",
      "ValueError: Value of 'color' is not the name of a column in 'data_frame'. Expected one of ['Unnamed: 0', 'Flight Number', 'Date', 'Time (UTC)', 'Booster Version', 'Launch Site', 'Payload', 'Payload Mass (kg)', 'Orbit', 'Customer', 'Landing Outcome', 'class', 'Lat', 'Long'] but received: Booster Version Category\n",
      "127.0.0.1 - - [12/May/2023 16:12:17] \"POST /_dash-update-component HTTP/1.1\" 500 -\n",
      "127.0.0.1 - - [12/May/2023 16:12:17] \"POST /_dash-update-component HTTP/1.1\" 200 -\n",
      "[2023-05-12 16:15:33,169] ERROR in app: Exception on /_dash-update-component [POST]\n",
      "Traceback (most recent call last):\n",
      "  File \"C:\\Users\\DELL\\AppData\\Roaming\\Python\\Python39\\site-packages\\flask\\app.py\", line 2528, in wsgi_app\n",
      "    response = self.full_dispatch_request()\n",
      "  File \"C:\\Users\\DELL\\AppData\\Roaming\\Python\\Python39\\site-packages\\flask\\app.py\", line 1825, in full_dispatch_request\n",
      "    rv = self.handle_user_exception(e)\n",
      "  File \"C:\\Users\\DELL\\AppData\\Roaming\\Python\\Python39\\site-packages\\flask\\app.py\", line 1823, in full_dispatch_request\n",
      "    rv = self.dispatch_request()\n",
      "  File \"C:\\Users\\DELL\\AppData\\Roaming\\Python\\Python39\\site-packages\\flask\\app.py\", line 1799, in dispatch_request\n",
      "    return self.ensure_sync(self.view_functions[rule.endpoint])(**view_args)\n",
      "  File \"C:\\ProgramData\\Anaconda3\\lib\\site-packages\\dash\\dash.py\", line 1283, in dispatch\n",
      "    ctx.run(\n",
      "  File \"C:\\ProgramData\\Anaconda3\\lib\\site-packages\\dash\\_callback.py\", line 450, in add_context\n",
      "    output_value = func(*func_args, **func_kwargs)  # %% callback invoked %%\n",
      "  File \"C:\\Users\\DELL\\AppData\\Local\\Temp\\ipykernel_16068\\3660098658.py\", line 10, in get_scatter_chart\n",
      "    return px.scatter(filtered_df,\n",
      "  File \"C:\\ProgramData\\Anaconda3\\lib\\site-packages\\plotly\\express\\_chart_types.py\", line 66, in scatter\n",
      "    return make_figure(args=locals(), constructor=go.Scatter)\n",
      "  File \"C:\\ProgramData\\Anaconda3\\lib\\site-packages\\plotly\\express\\_core.py\", line 1990, in make_figure\n",
      "    args = build_dataframe(args, constructor)\n",
      "  File \"C:\\ProgramData\\Anaconda3\\lib\\site-packages\\plotly\\express\\_core.py\", line 1405, in build_dataframe\n",
      "    df_output, wide_id_vars = process_args_into_dataframe(\n",
      "  File \"C:\\ProgramData\\Anaconda3\\lib\\site-packages\\plotly\\express\\_core.py\", line 1207, in process_args_into_dataframe\n",
      "    raise ValueError(err_msg)\n",
      "ValueError: Value of 'color' is not the name of a column in 'data_frame'. Expected one of ['Unnamed: 0', 'Flight Number', 'Date', 'Time (UTC)', 'Booster Version', 'Launch Site', 'Payload', 'Payload Mass (kg)', 'Orbit', 'Customer', 'Landing Outcome', 'class', 'Lat', 'Long'] but received: Booster Version Category\n",
      "127.0.0.1 - - [12/May/2023 16:15:33] \"POST /_dash-update-component HTTP/1.1\" 500 -\n",
      "[2023-05-12 16:15:43,231] ERROR in app: Exception on /_dash-update-component [POST]\n",
      "Traceback (most recent call last):\n",
      "  File \"C:\\Users\\DELL\\AppData\\Roaming\\Python\\Python39\\site-packages\\flask\\app.py\", line 2528, in wsgi_app\n",
      "    response = self.full_dispatch_request()\n",
      "  File \"C:\\Users\\DELL\\AppData\\Roaming\\Python\\Python39\\site-packages\\flask\\app.py\", line 1825, in full_dispatch_request\n",
      "    rv = self.handle_user_exception(e)\n",
      "  File \"C:\\Users\\DELL\\AppData\\Roaming\\Python\\Python39\\site-packages\\flask\\app.py\", line 1823, in full_dispatch_request\n",
      "    rv = self.dispatch_request()\n",
      "  File \"C:\\Users\\DELL\\AppData\\Roaming\\Python\\Python39\\site-packages\\flask\\app.py\", line 1799, in dispatch_request\n",
      "    return self.ensure_sync(self.view_functions[rule.endpoint])(**view_args)\n",
      "  File \"C:\\ProgramData\\Anaconda3\\lib\\site-packages\\dash\\dash.py\", line 1283, in dispatch\n",
      "    ctx.run(\n",
      "  File \"C:\\ProgramData\\Anaconda3\\lib\\site-packages\\dash\\_callback.py\", line 450, in add_context\n",
      "    output_value = func(*func_args, **func_kwargs)  # %% callback invoked %%\n",
      "  File \"C:\\Users\\DELL\\AppData\\Local\\Temp\\ipykernel_16068\\3660098658.py\", line 10, in get_scatter_chart\n",
      "    return px.scatter(filtered_df,\n",
      "  File \"C:\\ProgramData\\Anaconda3\\lib\\site-packages\\plotly\\express\\_chart_types.py\", line 66, in scatter\n",
      "    return make_figure(args=locals(), constructor=go.Scatter)\n",
      "  File \"C:\\ProgramData\\Anaconda3\\lib\\site-packages\\plotly\\express\\_core.py\", line 1990, in make_figure\n",
      "    args = build_dataframe(args, constructor)\n",
      "  File \"C:\\ProgramData\\Anaconda3\\lib\\site-packages\\plotly\\express\\_core.py\", line 1405, in build_dataframe\n",
      "    df_output, wide_id_vars = process_args_into_dataframe(\n",
      "  File \"C:\\ProgramData\\Anaconda3\\lib\\site-packages\\plotly\\express\\_core.py\", line 1207, in process_args_into_dataframe\n",
      "    raise ValueError(err_msg)\n",
      "ValueError: Value of 'color' is not the name of a column in 'data_frame'. Expected one of ['Unnamed: 0', 'Flight Number', 'Date', 'Time (UTC)', 'Booster Version', 'Launch Site', 'Payload', 'Payload Mass (kg)', 'Orbit', 'Customer', 'Landing Outcome', 'class', 'Lat', 'Long'] but received: Booster Version Category\n",
      "127.0.0.1 - - [12/May/2023 16:15:43] \"POST /_dash-update-component HTTP/1.1\" 500 -\n",
      "[2023-05-12 16:15:46,698] ERROR in app: Exception on /_dash-update-component [POST]\n",
      "Traceback (most recent call last):\n",
      "  File \"C:\\Users\\DELL\\AppData\\Roaming\\Python\\Python39\\site-packages\\flask\\app.py\", line 2528, in wsgi_app\n",
      "    response = self.full_dispatch_request()\n",
      "  File \"C:\\Users\\DELL\\AppData\\Roaming\\Python\\Python39\\site-packages\\flask\\app.py\", line 1825, in full_dispatch_request\n",
      "    rv = self.handle_user_exception(e)\n",
      "  File \"C:\\Users\\DELL\\AppData\\Roaming\\Python\\Python39\\site-packages\\flask\\app.py\", line 1823, in full_dispatch_request\n",
      "    rv = self.dispatch_request()\n",
      "  File \"C:\\Users\\DELL\\AppData\\Roaming\\Python\\Python39\\site-packages\\flask\\app.py\", line 1799, in dispatch_request\n",
      "    return self.ensure_sync(self.view_functions[rule.endpoint])(**view_args)\n",
      "  File \"C:\\ProgramData\\Anaconda3\\lib\\site-packages\\dash\\dash.py\", line 1283, in dispatch\n",
      "    ctx.run(\n",
      "  File \"C:\\ProgramData\\Anaconda3\\lib\\site-packages\\dash\\_callback.py\", line 450, in add_context\n",
      "    output_value = func(*func_args, **func_kwargs)  # %% callback invoked %%\n",
      "  File \"C:\\Users\\DELL\\AppData\\Local\\Temp\\ipykernel_16068\\3660098658.py\", line 10, in get_scatter_chart\n",
      "    return px.scatter(filtered_df,\n",
      "  File \"C:\\ProgramData\\Anaconda3\\lib\\site-packages\\plotly\\express\\_chart_types.py\", line 66, in scatter\n",
      "    return make_figure(args=locals(), constructor=go.Scatter)\n",
      "  File \"C:\\ProgramData\\Anaconda3\\lib\\site-packages\\plotly\\express\\_core.py\", line 1990, in make_figure\n",
      "    args = build_dataframe(args, constructor)\n",
      "  File \"C:\\ProgramData\\Anaconda3\\lib\\site-packages\\plotly\\express\\_core.py\", line 1405, in build_dataframe\n",
      "    df_output, wide_id_vars = process_args_into_dataframe(\n",
      "  File \"C:\\ProgramData\\Anaconda3\\lib\\site-packages\\plotly\\express\\_core.py\", line 1207, in process_args_into_dataframe\n",
      "    raise ValueError(err_msg)\n",
      "ValueError: Value of 'color' is not the name of a column in 'data_frame'. Expected one of ['Unnamed: 0', 'Flight Number', 'Date', 'Time (UTC)', 'Booster Version', 'Launch Site', 'Payload', 'Payload Mass (kg)', 'Orbit', 'Customer', 'Landing Outcome', 'class', 'Lat', 'Long'] but received: Booster Version Category\n"
     ]
    },
    {
     "name": "stderr",
     "output_type": "stream",
     "text": [
      "127.0.0.1 - - [12/May/2023 16:15:46] \"POST /_dash-update-component HTTP/1.1\" 500 -\n",
      "[2023-05-12 16:15:52,118] ERROR in app: Exception on /_dash-update-component [POST]\n",
      "Traceback (most recent call last):\n",
      "  File \"C:\\Users\\DELL\\AppData\\Roaming\\Python\\Python39\\site-packages\\flask\\app.py\", line 2528, in wsgi_app\n",
      "    response = self.full_dispatch_request()\n",
      "  File \"C:\\Users\\DELL\\AppData\\Roaming\\Python\\Python39\\site-packages\\flask\\app.py\", line 1825, in full_dispatch_request\n",
      "    rv = self.handle_user_exception(e)\n",
      "  File \"C:\\Users\\DELL\\AppData\\Roaming\\Python\\Python39\\site-packages\\flask\\app.py\", line 1823, in full_dispatch_request\n",
      "    rv = self.dispatch_request()\n",
      "  File \"C:\\Users\\DELL\\AppData\\Roaming\\Python\\Python39\\site-packages\\flask\\app.py\", line 1799, in dispatch_request\n",
      "    return self.ensure_sync(self.view_functions[rule.endpoint])(**view_args)\n",
      "  File \"C:\\ProgramData\\Anaconda3\\lib\\site-packages\\dash\\dash.py\", line 1283, in dispatch\n",
      "    ctx.run(\n",
      "  File \"C:\\ProgramData\\Anaconda3\\lib\\site-packages\\dash\\_callback.py\", line 450, in add_context\n",
      "    output_value = func(*func_args, **func_kwargs)  # %% callback invoked %%\n",
      "  File \"C:\\Users\\DELL\\AppData\\Local\\Temp\\ipykernel_16068\\3660098658.py\", line 10, in get_scatter_chart\n",
      "    return px.scatter(filtered_df,\n",
      "  File \"C:\\ProgramData\\Anaconda3\\lib\\site-packages\\plotly\\express\\_chart_types.py\", line 66, in scatter\n",
      "    return make_figure(args=locals(), constructor=go.Scatter)\n",
      "  File \"C:\\ProgramData\\Anaconda3\\lib\\site-packages\\plotly\\express\\_core.py\", line 1990, in make_figure\n",
      "    args = build_dataframe(args, constructor)\n",
      "  File \"C:\\ProgramData\\Anaconda3\\lib\\site-packages\\plotly\\express\\_core.py\", line 1405, in build_dataframe\n",
      "    df_output, wide_id_vars = process_args_into_dataframe(\n",
      "  File \"C:\\ProgramData\\Anaconda3\\lib\\site-packages\\plotly\\express\\_core.py\", line 1207, in process_args_into_dataframe\n",
      "    raise ValueError(err_msg)\n",
      "ValueError: Value of 'color' is not the name of a column in 'data_frame'. Expected one of ['Unnamed: 0', 'Flight Number', 'Date', 'Time (UTC)', 'Booster Version', 'Launch Site', 'Payload', 'Payload Mass (kg)', 'Orbit', 'Customer', 'Landing Outcome', 'class', 'Lat', 'Long'] but received: Booster Version Category\n",
      "127.0.0.1 - - [12/May/2023 16:15:52] \"POST /_dash-update-component HTTP/1.1\" 500 -\n",
      "[2023-05-12 16:16:30,415] ERROR in app: Exception on /_dash-update-component [POST]\n",
      "Traceback (most recent call last):\n",
      "  File \"C:\\Users\\DELL\\AppData\\Roaming\\Python\\Python39\\site-packages\\flask\\app.py\", line 2528, in wsgi_app\n",
      "    response = self.full_dispatch_request()\n",
      "  File \"C:\\Users\\DELL\\AppData\\Roaming\\Python\\Python39\\site-packages\\flask\\app.py\", line 1825, in full_dispatch_request\n",
      "    rv = self.handle_user_exception(e)\n",
      "  File \"C:\\Users\\DELL\\AppData\\Roaming\\Python\\Python39\\site-packages\\flask\\app.py\", line 1823, in full_dispatch_request\n",
      "    rv = self.dispatch_request()\n",
      "  File \"C:\\Users\\DELL\\AppData\\Roaming\\Python\\Python39\\site-packages\\flask\\app.py\", line 1799, in dispatch_request\n",
      "    return self.ensure_sync(self.view_functions[rule.endpoint])(**view_args)\n",
      "  File \"C:\\ProgramData\\Anaconda3\\lib\\site-packages\\dash\\dash.py\", line 1283, in dispatch\n",
      "    ctx.run(\n",
      "  File \"C:\\ProgramData\\Anaconda3\\lib\\site-packages\\dash\\_callback.py\", line 450, in add_context\n",
      "    output_value = func(*func_args, **func_kwargs)  # %% callback invoked %%\n",
      "  File \"C:\\Users\\DELL\\AppData\\Local\\Temp\\ipykernel_16068\\3660098658.py\", line 10, in get_scatter_chart\n",
      "    return px.scatter(filtered_df,\n",
      "  File \"C:\\ProgramData\\Anaconda3\\lib\\site-packages\\plotly\\express\\_chart_types.py\", line 66, in scatter\n",
      "    return make_figure(args=locals(), constructor=go.Scatter)\n",
      "  File \"C:\\ProgramData\\Anaconda3\\lib\\site-packages\\plotly\\express\\_core.py\", line 1990, in make_figure\n",
      "    args = build_dataframe(args, constructor)\n",
      "  File \"C:\\ProgramData\\Anaconda3\\lib\\site-packages\\plotly\\express\\_core.py\", line 1405, in build_dataframe\n",
      "    df_output, wide_id_vars = process_args_into_dataframe(\n",
      "  File \"C:\\ProgramData\\Anaconda3\\lib\\site-packages\\plotly\\express\\_core.py\", line 1207, in process_args_into_dataframe\n",
      "    raise ValueError(err_msg)\n",
      "ValueError: Value of 'color' is not the name of a column in 'data_frame'. Expected one of ['Unnamed: 0', 'Flight Number', 'Date', 'Time (UTC)', 'Booster Version', 'Launch Site', 'Payload', 'Payload Mass (kg)', 'Orbit', 'Customer', 'Landing Outcome', 'class', 'Lat', 'Long'] but received: Booster Version Category\n",
      "127.0.0.1 - - [12/May/2023 16:16:30] \"POST /_dash-update-component HTTP/1.1\" 500 -\n",
      "[2023-05-12 16:16:34,428] ERROR in app: Exception on /_dash-update-component [POST]\n",
      "Traceback (most recent call last):\n",
      "  File \"C:\\Users\\DELL\\AppData\\Roaming\\Python\\Python39\\site-packages\\flask\\app.py\", line 2528, in wsgi_app\n",
      "    response = self.full_dispatch_request()\n",
      "  File \"C:\\Users\\DELL\\AppData\\Roaming\\Python\\Python39\\site-packages\\flask\\app.py\", line 1825, in full_dispatch_request\n",
      "    rv = self.handle_user_exception(e)\n",
      "  File \"C:\\Users\\DELL\\AppData\\Roaming\\Python\\Python39\\site-packages\\flask\\app.py\", line 1823, in full_dispatch_request\n",
      "    rv = self.dispatch_request()\n",
      "  File \"C:\\Users\\DELL\\AppData\\Roaming\\Python\\Python39\\site-packages\\flask\\app.py\", line 1799, in dispatch_request\n",
      "    return self.ensure_sync(self.view_functions[rule.endpoint])(**view_args)\n",
      "  File \"C:\\ProgramData\\Anaconda3\\lib\\site-packages\\dash\\dash.py\", line 1283, in dispatch\n",
      "    ctx.run(\n",
      "  File \"C:\\ProgramData\\Anaconda3\\lib\\site-packages\\dash\\_callback.py\", line 450, in add_context\n",
      "    output_value = func(*func_args, **func_kwargs)  # %% callback invoked %%\n",
      "  File \"C:\\Users\\DELL\\AppData\\Local\\Temp\\ipykernel_16068\\3660098658.py\", line 10, in get_scatter_chart\n",
      "    return px.scatter(filtered_df,\n",
      "  File \"C:\\ProgramData\\Anaconda3\\lib\\site-packages\\plotly\\express\\_chart_types.py\", line 66, in scatter\n",
      "    return make_figure(args=locals(), constructor=go.Scatter)\n",
      "  File \"C:\\ProgramData\\Anaconda3\\lib\\site-packages\\plotly\\express\\_core.py\", line 1990, in make_figure\n",
      "    args = build_dataframe(args, constructor)\n",
      "  File \"C:\\ProgramData\\Anaconda3\\lib\\site-packages\\plotly\\express\\_core.py\", line 1405, in build_dataframe\n",
      "    df_output, wide_id_vars = process_args_into_dataframe(\n",
      "  File \"C:\\ProgramData\\Anaconda3\\lib\\site-packages\\plotly\\express\\_core.py\", line 1207, in process_args_into_dataframe\n",
      "    raise ValueError(err_msg)\n",
      "ValueError: Value of 'color' is not the name of a column in 'data_frame'. Expected one of ['Unnamed: 0', 'Flight Number', 'Date', 'Time (UTC)', 'Booster Version', 'Launch Site', 'Payload', 'Payload Mass (kg)', 'Orbit', 'Customer', 'Landing Outcome', 'class', 'Lat', 'Long'] but received: Booster Version Category\n",
      "127.0.0.1 - - [12/May/2023 16:16:34] \"POST /_dash-update-component HTTP/1.1\" 500 -\n",
      "C:\\Users\\DELL\\AppData\\Local\\Temp\\ipykernel_16068\\2431199016.py:10: SettingWithCopyWarning:\n",
      "\n",
      "\n",
      "A value is trying to be set on a copy of a slice from a DataFrame.\n",
      "Try using .loc[row_indexer,col_indexer] = value instead\n",
      "\n",
      "See the caveats in the documentation: https://pandas.pydata.org/pandas-docs/stable/user_guide/indexing.html#returning-a-view-versus-a-copy\n",
      "\n",
      "C:\\Users\\DELL\\AppData\\Local\\Temp\\ipykernel_16068\\2431199016.py:11: SettingWithCopyWarning:\n",
      "\n",
      "\n",
      "A value is trying to be set on a copy of a slice from a DataFrame.\n",
      "Try using .loc[row_indexer,col_indexer] = value instead\n",
      "\n",
      "See the caveats in the documentation: https://pandas.pydata.org/pandas-docs/stable/user_guide/indexing.html#returning-a-view-versus-a-copy\n",
      "\n",
      "127.0.0.1 - - [12/May/2023 16:18:41] \"POST /_dash-update-component HTTP/1.1\" 200 -\n",
      "[2023-05-12 16:18:41,378] ERROR in app: Exception on /_dash-update-component [POST]\n",
      "Traceback (most recent call last):\n",
      "  File \"C:\\Users\\DELL\\AppData\\Roaming\\Python\\Python39\\site-packages\\flask\\app.py\", line 2528, in wsgi_app\n",
      "    response = self.full_dispatch_request()\n",
      "  File \"C:\\Users\\DELL\\AppData\\Roaming\\Python\\Python39\\site-packages\\flask\\app.py\", line 1825, in full_dispatch_request\n",
      "    rv = self.handle_user_exception(e)\n",
      "  File \"C:\\Users\\DELL\\AppData\\Roaming\\Python\\Python39\\site-packages\\flask\\app.py\", line 1823, in full_dispatch_request\n",
      "    rv = self.dispatch_request()\n",
      "  File \"C:\\Users\\DELL\\AppData\\Roaming\\Python\\Python39\\site-packages\\flask\\app.py\", line 1799, in dispatch_request\n",
      "    return self.ensure_sync(self.view_functions[rule.endpoint])(**view_args)\n",
      "  File \"C:\\ProgramData\\Anaconda3\\lib\\site-packages\\dash\\dash.py\", line 1283, in dispatch\n",
      "    ctx.run(\n",
      "  File \"C:\\ProgramData\\Anaconda3\\lib\\site-packages\\dash\\_callback.py\", line 450, in add_context\n",
      "    output_value = func(*func_args, **func_kwargs)  # %% callback invoked %%\n",
      "  File \"C:\\Users\\DELL\\AppData\\Local\\Temp\\ipykernel_16068\\3660098658.py\", line 18, in get_scatter_chart\n",
      "    return px.scatter (filtered_df,\n",
      "  File \"C:\\ProgramData\\Anaconda3\\lib\\site-packages\\plotly\\express\\_chart_types.py\", line 66, in scatter\n",
      "    return make_figure(args=locals(), constructor=go.Scatter)\n",
      "  File \"C:\\ProgramData\\Anaconda3\\lib\\site-packages\\plotly\\express\\_core.py\", line 1990, in make_figure\n",
      "    args = build_dataframe(args, constructor)\n",
      "  File \"C:\\ProgramData\\Anaconda3\\lib\\site-packages\\plotly\\express\\_core.py\", line 1405, in build_dataframe\n",
      "    df_output, wide_id_vars = process_args_into_dataframe(\n",
      "  File \"C:\\ProgramData\\Anaconda3\\lib\\site-packages\\plotly\\express\\_core.py\", line 1207, in process_args_into_dataframe\n",
      "    raise ValueError(err_msg)\n",
      "ValueError: Value of 'color' is not the name of a column in 'data_frame'. Expected one of ['Unnamed: 0', 'Flight Number', 'Date', 'Time (UTC)', 'Booster Version', 'Launch Site', 'Payload', 'Payload Mass (kg)', 'Orbit', 'Customer', 'Landing Outcome', 'class', 'Lat', 'Long', 'outcome', 'counts'] but received: Booster Version Category\n"
     ]
    },
    {
     "name": "stderr",
     "output_type": "stream",
     "text": [
      "127.0.0.1 - - [12/May/2023 16:18:41] \"POST /_dash-update-component HTTP/1.1\" 500 -\n",
      "127.0.0.1 - - [12/May/2023 16:19:44] \"POST /_dash-update-component HTTP/1.1\" 200 -\n",
      "[2023-05-12 16:19:44,762] ERROR in app: Exception on /_dash-update-component [POST]\n",
      "Traceback (most recent call last):\n",
      "  File \"C:\\Users\\DELL\\AppData\\Roaming\\Python\\Python39\\site-packages\\flask\\app.py\", line 2528, in wsgi_app\n",
      "    response = self.full_dispatch_request()\n",
      "  File \"C:\\Users\\DELL\\AppData\\Roaming\\Python\\Python39\\site-packages\\flask\\app.py\", line 1825, in full_dispatch_request\n",
      "    rv = self.handle_user_exception(e)\n",
      "  File \"C:\\Users\\DELL\\AppData\\Roaming\\Python\\Python39\\site-packages\\flask\\app.py\", line 1823, in full_dispatch_request\n",
      "    rv = self.dispatch_request()\n",
      "  File \"C:\\Users\\DELL\\AppData\\Roaming\\Python\\Python39\\site-packages\\flask\\app.py\", line 1799, in dispatch_request\n",
      "    return self.ensure_sync(self.view_functions[rule.endpoint])(**view_args)\n",
      "  File \"C:\\ProgramData\\Anaconda3\\lib\\site-packages\\dash\\dash.py\", line 1283, in dispatch\n",
      "    ctx.run(\n",
      "  File \"C:\\ProgramData\\Anaconda3\\lib\\site-packages\\dash\\_callback.py\", line 450, in add_context\n",
      "    output_value = func(*func_args, **func_kwargs)  # %% callback invoked %%\n",
      "  File \"C:\\Users\\DELL\\AppData\\Local\\Temp\\ipykernel_16068\\3660098658.py\", line 10, in get_scatter_chart\n",
      "    return px.scatter(filtered_df,\n",
      "  File \"C:\\ProgramData\\Anaconda3\\lib\\site-packages\\plotly\\express\\_chart_types.py\", line 66, in scatter\n",
      "    return make_figure(args=locals(), constructor=go.Scatter)\n",
      "  File \"C:\\ProgramData\\Anaconda3\\lib\\site-packages\\plotly\\express\\_core.py\", line 1990, in make_figure\n",
      "    args = build_dataframe(args, constructor)\n",
      "  File \"C:\\ProgramData\\Anaconda3\\lib\\site-packages\\plotly\\express\\_core.py\", line 1405, in build_dataframe\n",
      "    df_output, wide_id_vars = process_args_into_dataframe(\n",
      "  File \"C:\\ProgramData\\Anaconda3\\lib\\site-packages\\plotly\\express\\_core.py\", line 1207, in process_args_into_dataframe\n",
      "    raise ValueError(err_msg)\n",
      "ValueError: Value of 'color' is not the name of a column in 'data_frame'. Expected one of ['Unnamed: 0', 'Flight Number', 'Date', 'Time (UTC)', 'Booster Version', 'Launch Site', 'Payload', 'Payload Mass (kg)', 'Orbit', 'Customer', 'Landing Outcome', 'class', 'Lat', 'Long'] but received: Booster Version Category\n",
      "127.0.0.1 - - [12/May/2023 16:19:44] \"POST /_dash-update-component HTTP/1.1\" 500 -\n",
      "C:\\Users\\DELL\\AppData\\Local\\Temp\\ipykernel_16068\\2431199016.py:10: SettingWithCopyWarning:\n",
      "\n",
      "\n",
      "A value is trying to be set on a copy of a slice from a DataFrame.\n",
      "Try using .loc[row_indexer,col_indexer] = value instead\n",
      "\n",
      "See the caveats in the documentation: https://pandas.pydata.org/pandas-docs/stable/user_guide/indexing.html#returning-a-view-versus-a-copy\n",
      "\n",
      "C:\\Users\\DELL\\AppData\\Local\\Temp\\ipykernel_16068\\2431199016.py:11: SettingWithCopyWarning:\n",
      "\n",
      "\n",
      "A value is trying to be set on a copy of a slice from a DataFrame.\n",
      "Try using .loc[row_indexer,col_indexer] = value instead\n",
      "\n",
      "See the caveats in the documentation: https://pandas.pydata.org/pandas-docs/stable/user_guide/indexing.html#returning-a-view-versus-a-copy\n",
      "\n",
      "127.0.0.1 - - [12/May/2023 16:20:08] \"POST /_dash-update-component HTTP/1.1\" 200 -\n",
      "[2023-05-12 16:20:08,631] ERROR in app: Exception on /_dash-update-component [POST]\n",
      "Traceback (most recent call last):\n",
      "  File \"C:\\Users\\DELL\\AppData\\Roaming\\Python\\Python39\\site-packages\\flask\\app.py\", line 2528, in wsgi_app\n",
      "    response = self.full_dispatch_request()\n",
      "  File \"C:\\Users\\DELL\\AppData\\Roaming\\Python\\Python39\\site-packages\\flask\\app.py\", line 1825, in full_dispatch_request\n",
      "    rv = self.handle_user_exception(e)\n",
      "  File \"C:\\Users\\DELL\\AppData\\Roaming\\Python\\Python39\\site-packages\\flask\\app.py\", line 1823, in full_dispatch_request\n",
      "    rv = self.dispatch_request()\n",
      "  File \"C:\\Users\\DELL\\AppData\\Roaming\\Python\\Python39\\site-packages\\flask\\app.py\", line 1799, in dispatch_request\n",
      "    return self.ensure_sync(self.view_functions[rule.endpoint])(**view_args)\n",
      "  File \"C:\\ProgramData\\Anaconda3\\lib\\site-packages\\dash\\dash.py\", line 1283, in dispatch\n",
      "    ctx.run(\n",
      "  File \"C:\\ProgramData\\Anaconda3\\lib\\site-packages\\dash\\_callback.py\", line 450, in add_context\n",
      "    output_value = func(*func_args, **func_kwargs)  # %% callback invoked %%\n",
      "  File \"C:\\Users\\DELL\\AppData\\Local\\Temp\\ipykernel_16068\\3660098658.py\", line 18, in get_scatter_chart\n",
      "    return px.scatter (filtered_df,\n",
      "  File \"C:\\ProgramData\\Anaconda3\\lib\\site-packages\\plotly\\express\\_chart_types.py\", line 66, in scatter\n",
      "    return make_figure(args=locals(), constructor=go.Scatter)\n",
      "  File \"C:\\ProgramData\\Anaconda3\\lib\\site-packages\\plotly\\express\\_core.py\", line 1990, in make_figure\n",
      "    args = build_dataframe(args, constructor)\n",
      "  File \"C:\\ProgramData\\Anaconda3\\lib\\site-packages\\plotly\\express\\_core.py\", line 1405, in build_dataframe\n",
      "    df_output, wide_id_vars = process_args_into_dataframe(\n",
      "  File \"C:\\ProgramData\\Anaconda3\\lib\\site-packages\\plotly\\express\\_core.py\", line 1207, in process_args_into_dataframe\n",
      "    raise ValueError(err_msg)\n",
      "ValueError: Value of 'color' is not the name of a column in 'data_frame'. Expected one of ['Unnamed: 0', 'Flight Number', 'Date', 'Time (UTC)', 'Booster Version', 'Launch Site', 'Payload', 'Payload Mass (kg)', 'Orbit', 'Customer', 'Landing Outcome', 'class', 'Lat', 'Long', 'outcome', 'counts'] but received: Booster Version Category\n",
      "127.0.0.1 - - [12/May/2023 16:20:08] \"POST /_dash-update-component HTTP/1.1\" 500 -\n",
      "C:\\Users\\DELL\\AppData\\Local\\Temp\\ipykernel_16068\\2431199016.py:10: SettingWithCopyWarning:\n",
      "\n",
      "\n",
      "A value is trying to be set on a copy of a slice from a DataFrame.\n",
      "Try using .loc[row_indexer,col_indexer] = value instead\n",
      "\n",
      "See the caveats in the documentation: https://pandas.pydata.org/pandas-docs/stable/user_guide/indexing.html#returning-a-view-versus-a-copy\n",
      "\n",
      "C:\\Users\\DELL\\AppData\\Local\\Temp\\ipykernel_16068\\2431199016.py:11: SettingWithCopyWarning:\n",
      "\n",
      "\n",
      "A value is trying to be set on a copy of a slice from a DataFrame.\n",
      "Try using .loc[row_indexer,col_indexer] = value instead\n",
      "\n",
      "See the caveats in the documentation: https://pandas.pydata.org/pandas-docs/stable/user_guide/indexing.html#returning-a-view-versus-a-copy\n",
      "\n",
      "127.0.0.1 - - [12/May/2023 16:20:20] \"POST /_dash-update-component HTTP/1.1\" 200 -\n",
      "[2023-05-12 16:20:20,580] ERROR in app: Exception on /_dash-update-component [POST]\n",
      "Traceback (most recent call last):\n",
      "  File \"C:\\Users\\DELL\\AppData\\Roaming\\Python\\Python39\\site-packages\\flask\\app.py\", line 2528, in wsgi_app\n",
      "    response = self.full_dispatch_request()\n",
      "  File \"C:\\Users\\DELL\\AppData\\Roaming\\Python\\Python39\\site-packages\\flask\\app.py\", line 1825, in full_dispatch_request\n",
      "    rv = self.handle_user_exception(e)\n",
      "  File \"C:\\Users\\DELL\\AppData\\Roaming\\Python\\Python39\\site-packages\\flask\\app.py\", line 1823, in full_dispatch_request\n",
      "    rv = self.dispatch_request()\n",
      "  File \"C:\\Users\\DELL\\AppData\\Roaming\\Python\\Python39\\site-packages\\flask\\app.py\", line 1799, in dispatch_request\n",
      "    return self.ensure_sync(self.view_functions[rule.endpoint])(**view_args)\n",
      "  File \"C:\\ProgramData\\Anaconda3\\lib\\site-packages\\dash\\dash.py\", line 1283, in dispatch\n",
      "    ctx.run(\n",
      "  File \"C:\\ProgramData\\Anaconda3\\lib\\site-packages\\dash\\_callback.py\", line 450, in add_context\n",
      "    output_value = func(*func_args, **func_kwargs)  # %% callback invoked %%\n",
      "  File \"C:\\Users\\DELL\\AppData\\Local\\Temp\\ipykernel_16068\\3660098658.py\", line 18, in get_scatter_chart\n",
      "    return px.scatter (filtered_df,\n",
      "  File \"C:\\ProgramData\\Anaconda3\\lib\\site-packages\\plotly\\express\\_chart_types.py\", line 66, in scatter\n",
      "    return make_figure(args=locals(), constructor=go.Scatter)\n",
      "  File \"C:\\ProgramData\\Anaconda3\\lib\\site-packages\\plotly\\express\\_core.py\", line 1990, in make_figure\n",
      "    args = build_dataframe(args, constructor)\n",
      "  File \"C:\\ProgramData\\Anaconda3\\lib\\site-packages\\plotly\\express\\_core.py\", line 1405, in build_dataframe\n",
      "    df_output, wide_id_vars = process_args_into_dataframe(\n",
      "  File \"C:\\ProgramData\\Anaconda3\\lib\\site-packages\\plotly\\express\\_core.py\", line 1207, in process_args_into_dataframe\n",
      "    raise ValueError(err_msg)\n",
      "ValueError: Value of 'color' is not the name of a column in 'data_frame'. Expected one of ['Unnamed: 0', 'Flight Number', 'Date', 'Time (UTC)', 'Booster Version', 'Launch Site', 'Payload', 'Payload Mass (kg)', 'Orbit', 'Customer', 'Landing Outcome', 'class', 'Lat', 'Long', 'outcome', 'counts'] but received: Booster Version Category\n"
     ]
    },
    {
     "name": "stderr",
     "output_type": "stream",
     "text": [
      "127.0.0.1 - - [12/May/2023 16:20:20] \"POST /_dash-update-component HTTP/1.1\" 500 -\n",
      "C:\\Users\\DELL\\AppData\\Local\\Temp\\ipykernel_16068\\2431199016.py:10: SettingWithCopyWarning:\n",
      "\n",
      "\n",
      "A value is trying to be set on a copy of a slice from a DataFrame.\n",
      "Try using .loc[row_indexer,col_indexer] = value instead\n",
      "\n",
      "See the caveats in the documentation: https://pandas.pydata.org/pandas-docs/stable/user_guide/indexing.html#returning-a-view-versus-a-copy\n",
      "\n",
      "C:\\Users\\DELL\\AppData\\Local\\Temp\\ipykernel_16068\\2431199016.py:11: SettingWithCopyWarning:\n",
      "\n",
      "\n",
      "A value is trying to be set on a copy of a slice from a DataFrame.\n",
      "Try using .loc[row_indexer,col_indexer] = value instead\n",
      "\n",
      "See the caveats in the documentation: https://pandas.pydata.org/pandas-docs/stable/user_guide/indexing.html#returning-a-view-versus-a-copy\n",
      "\n",
      "127.0.0.1 - - [12/May/2023 16:20:27] \"POST /_dash-update-component HTTP/1.1\" 200 -\n",
      "[2023-05-12 16:20:27,264] ERROR in app: Exception on /_dash-update-component [POST]\n",
      "Traceback (most recent call last):\n",
      "  File \"C:\\Users\\DELL\\AppData\\Roaming\\Python\\Python39\\site-packages\\flask\\app.py\", line 2528, in wsgi_app\n",
      "    response = self.full_dispatch_request()\n",
      "  File \"C:\\Users\\DELL\\AppData\\Roaming\\Python\\Python39\\site-packages\\flask\\app.py\", line 1825, in full_dispatch_request\n",
      "    rv = self.handle_user_exception(e)\n",
      "  File \"C:\\Users\\DELL\\AppData\\Roaming\\Python\\Python39\\site-packages\\flask\\app.py\", line 1823, in full_dispatch_request\n",
      "    rv = self.dispatch_request()\n",
      "  File \"C:\\Users\\DELL\\AppData\\Roaming\\Python\\Python39\\site-packages\\flask\\app.py\", line 1799, in dispatch_request\n",
      "    return self.ensure_sync(self.view_functions[rule.endpoint])(**view_args)\n",
      "  File \"C:\\ProgramData\\Anaconda3\\lib\\site-packages\\dash\\dash.py\", line 1283, in dispatch\n",
      "    ctx.run(\n",
      "  File \"C:\\ProgramData\\Anaconda3\\lib\\site-packages\\dash\\_callback.py\", line 450, in add_context\n",
      "    output_value = func(*func_args, **func_kwargs)  # %% callback invoked %%\n",
      "  File \"C:\\Users\\DELL\\AppData\\Local\\Temp\\ipykernel_16068\\3660098658.py\", line 18, in get_scatter_chart\n",
      "    return px.scatter (filtered_df,\n",
      "  File \"C:\\ProgramData\\Anaconda3\\lib\\site-packages\\plotly\\express\\_chart_types.py\", line 66, in scatter\n",
      "    return make_figure(args=locals(), constructor=go.Scatter)\n",
      "  File \"C:\\ProgramData\\Anaconda3\\lib\\site-packages\\plotly\\express\\_core.py\", line 1990, in make_figure\n",
      "    args = build_dataframe(args, constructor)\n",
      "  File \"C:\\ProgramData\\Anaconda3\\lib\\site-packages\\plotly\\express\\_core.py\", line 1405, in build_dataframe\n",
      "    df_output, wide_id_vars = process_args_into_dataframe(\n",
      "  File \"C:\\ProgramData\\Anaconda3\\lib\\site-packages\\plotly\\express\\_core.py\", line 1207, in process_args_into_dataframe\n",
      "    raise ValueError(err_msg)\n",
      "ValueError: Value of 'color' is not the name of a column in 'data_frame'. Expected one of ['Unnamed: 0', 'Flight Number', 'Date', 'Time (UTC)', 'Booster Version', 'Launch Site', 'Payload', 'Payload Mass (kg)', 'Orbit', 'Customer', 'Landing Outcome', 'class', 'Lat', 'Long', 'outcome', 'counts'] but received: Booster Version Category\n",
      "127.0.0.1 - - [12/May/2023 16:20:27] \"POST /_dash-update-component HTTP/1.1\" 500 -\n",
      "C:\\Users\\DELL\\AppData\\Local\\Temp\\ipykernel_16068\\2431199016.py:10: SettingWithCopyWarning:\n",
      "\n",
      "\n",
      "A value is trying to be set on a copy of a slice from a DataFrame.\n",
      "Try using .loc[row_indexer,col_indexer] = value instead\n",
      "\n",
      "See the caveats in the documentation: https://pandas.pydata.org/pandas-docs/stable/user_guide/indexing.html#returning-a-view-versus-a-copy\n",
      "\n",
      "C:\\Users\\DELL\\AppData\\Local\\Temp\\ipykernel_16068\\2431199016.py:11: SettingWithCopyWarning:\n",
      "\n",
      "\n",
      "A value is trying to be set on a copy of a slice from a DataFrame.\n",
      "Try using .loc[row_indexer,col_indexer] = value instead\n",
      "\n",
      "See the caveats in the documentation: https://pandas.pydata.org/pandas-docs/stable/user_guide/indexing.html#returning-a-view-versus-a-copy\n",
      "\n",
      "127.0.0.1 - - [12/May/2023 16:20:31] \"POST /_dash-update-component HTTP/1.1\" 200 -\n",
      "[2023-05-12 16:20:31,783] ERROR in app: Exception on /_dash-update-component [POST]\n",
      "Traceback (most recent call last):\n",
      "  File \"C:\\Users\\DELL\\AppData\\Roaming\\Python\\Python39\\site-packages\\flask\\app.py\", line 2528, in wsgi_app\n",
      "    response = self.full_dispatch_request()\n",
      "  File \"C:\\Users\\DELL\\AppData\\Roaming\\Python\\Python39\\site-packages\\flask\\app.py\", line 1825, in full_dispatch_request\n",
      "    rv = self.handle_user_exception(e)\n",
      "  File \"C:\\Users\\DELL\\AppData\\Roaming\\Python\\Python39\\site-packages\\flask\\app.py\", line 1823, in full_dispatch_request\n",
      "    rv = self.dispatch_request()\n",
      "  File \"C:\\Users\\DELL\\AppData\\Roaming\\Python\\Python39\\site-packages\\flask\\app.py\", line 1799, in dispatch_request\n",
      "    return self.ensure_sync(self.view_functions[rule.endpoint])(**view_args)\n",
      "  File \"C:\\ProgramData\\Anaconda3\\lib\\site-packages\\dash\\dash.py\", line 1283, in dispatch\n",
      "    ctx.run(\n",
      "  File \"C:\\ProgramData\\Anaconda3\\lib\\site-packages\\dash\\_callback.py\", line 450, in add_context\n",
      "    output_value = func(*func_args, **func_kwargs)  # %% callback invoked %%\n",
      "  File \"C:\\Users\\DELL\\AppData\\Local\\Temp\\ipykernel_16068\\3660098658.py\", line 18, in get_scatter_chart\n",
      "    return px.scatter (filtered_df,\n",
      "  File \"C:\\ProgramData\\Anaconda3\\lib\\site-packages\\plotly\\express\\_chart_types.py\", line 66, in scatter\n",
      "    return make_figure(args=locals(), constructor=go.Scatter)\n",
      "  File \"C:\\ProgramData\\Anaconda3\\lib\\site-packages\\plotly\\express\\_core.py\", line 1990, in make_figure\n",
      "    args = build_dataframe(args, constructor)\n",
      "  File \"C:\\ProgramData\\Anaconda3\\lib\\site-packages\\plotly\\express\\_core.py\", line 1405, in build_dataframe\n",
      "    df_output, wide_id_vars = process_args_into_dataframe(\n",
      "  File \"C:\\ProgramData\\Anaconda3\\lib\\site-packages\\plotly\\express\\_core.py\", line 1207, in process_args_into_dataframe\n",
      "    raise ValueError(err_msg)\n",
      "ValueError: Value of 'color' is not the name of a column in 'data_frame'. Expected one of ['Unnamed: 0', 'Flight Number', 'Date', 'Time (UTC)', 'Booster Version', 'Launch Site', 'Payload', 'Payload Mass (kg)', 'Orbit', 'Customer', 'Landing Outcome', 'class', 'Lat', 'Long', 'outcome', 'counts'] but received: Booster Version Category\n",
      "127.0.0.1 - - [12/May/2023 16:20:31] \"POST /_dash-update-component HTTP/1.1\" 500 -\n",
      "C:\\Users\\DELL\\AppData\\Local\\Temp\\ipykernel_16068\\2431199016.py:10: SettingWithCopyWarning:\n",
      "\n",
      "\n",
      "A value is trying to be set on a copy of a slice from a DataFrame.\n",
      "Try using .loc[row_indexer,col_indexer] = value instead\n",
      "\n",
      "See the caveats in the documentation: https://pandas.pydata.org/pandas-docs/stable/user_guide/indexing.html#returning-a-view-versus-a-copy\n",
      "\n",
      "C:\\Users\\DELL\\AppData\\Local\\Temp\\ipykernel_16068\\2431199016.py:11: SettingWithCopyWarning:\n",
      "\n",
      "\n",
      "A value is trying to be set on a copy of a slice from a DataFrame.\n",
      "Try using .loc[row_indexer,col_indexer] = value instead\n",
      "\n",
      "See the caveats in the documentation: https://pandas.pydata.org/pandas-docs/stable/user_guide/indexing.html#returning-a-view-versus-a-copy\n",
      "\n",
      "127.0.0.1 - - [12/May/2023 16:20:39] \"POST /_dash-update-component HTTP/1.1\" 200 -\n",
      "[2023-05-12 16:20:39,828] ERROR in app: Exception on /_dash-update-component [POST]\n",
      "Traceback (most recent call last):\n",
      "  File \"C:\\Users\\DELL\\AppData\\Roaming\\Python\\Python39\\site-packages\\flask\\app.py\", line 2528, in wsgi_app\n",
      "    response = self.full_dispatch_request()\n",
      "  File \"C:\\Users\\DELL\\AppData\\Roaming\\Python\\Python39\\site-packages\\flask\\app.py\", line 1825, in full_dispatch_request\n",
      "    rv = self.handle_user_exception(e)\n",
      "  File \"C:\\Users\\DELL\\AppData\\Roaming\\Python\\Python39\\site-packages\\flask\\app.py\", line 1823, in full_dispatch_request\n",
      "    rv = self.dispatch_request()\n",
      "  File \"C:\\Users\\DELL\\AppData\\Roaming\\Python\\Python39\\site-packages\\flask\\app.py\", line 1799, in dispatch_request\n",
      "    return self.ensure_sync(self.view_functions[rule.endpoint])(**view_args)\n",
      "  File \"C:\\ProgramData\\Anaconda3\\lib\\site-packages\\dash\\dash.py\", line 1283, in dispatch\n",
      "    ctx.run(\n",
      "  File \"C:\\ProgramData\\Anaconda3\\lib\\site-packages\\dash\\_callback.py\", line 450, in add_context\n",
      "    output_value = func(*func_args, **func_kwargs)  # %% callback invoked %%\n",
      "  File \"C:\\Users\\DELL\\AppData\\Local\\Temp\\ipykernel_16068\\3660098658.py\", line 18, in get_scatter_chart\n",
      "    return px.scatter (filtered_df,\n",
      "  File \"C:\\ProgramData\\Anaconda3\\lib\\site-packages\\plotly\\express\\_chart_types.py\", line 66, in scatter\n",
      "    return make_figure(args=locals(), constructor=go.Scatter)\n",
      "  File \"C:\\ProgramData\\Anaconda3\\lib\\site-packages\\plotly\\express\\_core.py\", line 1990, in make_figure\n",
      "    args = build_dataframe(args, constructor)\n",
      "  File \"C:\\ProgramData\\Anaconda3\\lib\\site-packages\\plotly\\express\\_core.py\", line 1405, in build_dataframe\n",
      "    df_output, wide_id_vars = process_args_into_dataframe(\n",
      "  File \"C:\\ProgramData\\Anaconda3\\lib\\site-packages\\plotly\\express\\_core.py\", line 1207, in process_args_into_dataframe\n",
      "    raise ValueError(err_msg)\n",
      "ValueError: Value of 'color' is not the name of a column in 'data_frame'. Expected one of ['Unnamed: 0', 'Flight Number', 'Date', 'Time (UTC)', 'Booster Version', 'Launch Site', 'Payload', 'Payload Mass (kg)', 'Orbit', 'Customer', 'Landing Outcome', 'class', 'Lat', 'Long', 'outcome', 'counts'] but received: Booster Version Category\n"
     ]
    },
    {
     "name": "stderr",
     "output_type": "stream",
     "text": [
      "127.0.0.1 - - [12/May/2023 16:20:39] \"POST /_dash-update-component HTTP/1.1\" 500 -\n",
      "C:\\Users\\DELL\\AppData\\Local\\Temp\\ipykernel_16068\\2431199016.py:10: SettingWithCopyWarning:\n",
      "\n",
      "\n",
      "A value is trying to be set on a copy of a slice from a DataFrame.\n",
      "Try using .loc[row_indexer,col_indexer] = value instead\n",
      "\n",
      "See the caveats in the documentation: https://pandas.pydata.org/pandas-docs/stable/user_guide/indexing.html#returning-a-view-versus-a-copy\n",
      "\n",
      "C:\\Users\\DELL\\AppData\\Local\\Temp\\ipykernel_16068\\2431199016.py:11: SettingWithCopyWarning:\n",
      "\n",
      "\n",
      "A value is trying to be set on a copy of a slice from a DataFrame.\n",
      "Try using .loc[row_indexer,col_indexer] = value instead\n",
      "\n",
      "See the caveats in the documentation: https://pandas.pydata.org/pandas-docs/stable/user_guide/indexing.html#returning-a-view-versus-a-copy\n",
      "\n",
      "127.0.0.1 - - [12/May/2023 16:20:52] \"POST /_dash-update-component HTTP/1.1\" 200 -\n",
      "[2023-05-12 16:20:52,645] ERROR in app: Exception on /_dash-update-component [POST]\n",
      "Traceback (most recent call last):\n",
      "  File \"C:\\Users\\DELL\\AppData\\Roaming\\Python\\Python39\\site-packages\\flask\\app.py\", line 2528, in wsgi_app\n",
      "    response = self.full_dispatch_request()\n",
      "  File \"C:\\Users\\DELL\\AppData\\Roaming\\Python\\Python39\\site-packages\\flask\\app.py\", line 1825, in full_dispatch_request\n",
      "    rv = self.handle_user_exception(e)\n",
      "  File \"C:\\Users\\DELL\\AppData\\Roaming\\Python\\Python39\\site-packages\\flask\\app.py\", line 1823, in full_dispatch_request\n",
      "    rv = self.dispatch_request()\n",
      "  File \"C:\\Users\\DELL\\AppData\\Roaming\\Python\\Python39\\site-packages\\flask\\app.py\", line 1799, in dispatch_request\n",
      "    return self.ensure_sync(self.view_functions[rule.endpoint])(**view_args)\n",
      "  File \"C:\\ProgramData\\Anaconda3\\lib\\site-packages\\dash\\dash.py\", line 1283, in dispatch\n",
      "    ctx.run(\n",
      "  File \"C:\\ProgramData\\Anaconda3\\lib\\site-packages\\dash\\_callback.py\", line 450, in add_context\n",
      "    output_value = func(*func_args, **func_kwargs)  # %% callback invoked %%\n",
      "  File \"C:\\Users\\DELL\\AppData\\Local\\Temp\\ipykernel_16068\\3660098658.py\", line 18, in get_scatter_chart\n",
      "    return px.scatter (filtered_df,\n",
      "  File \"C:\\ProgramData\\Anaconda3\\lib\\site-packages\\plotly\\express\\_chart_types.py\", line 66, in scatter\n",
      "    return make_figure(args=locals(), constructor=go.Scatter)\n",
      "  File \"C:\\ProgramData\\Anaconda3\\lib\\site-packages\\plotly\\express\\_core.py\", line 1990, in make_figure\n",
      "    args = build_dataframe(args, constructor)\n",
      "  File \"C:\\ProgramData\\Anaconda3\\lib\\site-packages\\plotly\\express\\_core.py\", line 1405, in build_dataframe\n",
      "    df_output, wide_id_vars = process_args_into_dataframe(\n",
      "  File \"C:\\ProgramData\\Anaconda3\\lib\\site-packages\\plotly\\express\\_core.py\", line 1207, in process_args_into_dataframe\n",
      "    raise ValueError(err_msg)\n",
      "ValueError: Value of 'color' is not the name of a column in 'data_frame'. Expected one of ['Unnamed: 0', 'Flight Number', 'Date', 'Time (UTC)', 'Booster Version', 'Launch Site', 'Payload', 'Payload Mass (kg)', 'Orbit', 'Customer', 'Landing Outcome', 'class', 'Lat', 'Long', 'outcome', 'counts'] but received: Booster Version Category\n",
      "127.0.0.1 - - [12/May/2023 16:20:52] \"POST /_dash-update-component HTTP/1.1\" 500 -\n",
      "C:\\Users\\DELL\\AppData\\Local\\Temp\\ipykernel_16068\\2431199016.py:10: SettingWithCopyWarning:\n",
      "\n",
      "\n",
      "A value is trying to be set on a copy of a slice from a DataFrame.\n",
      "Try using .loc[row_indexer,col_indexer] = value instead\n",
      "\n",
      "See the caveats in the documentation: https://pandas.pydata.org/pandas-docs/stable/user_guide/indexing.html#returning-a-view-versus-a-copy\n",
      "\n",
      "C:\\Users\\DELL\\AppData\\Local\\Temp\\ipykernel_16068\\2431199016.py:11: SettingWithCopyWarning:\n",
      "\n",
      "\n",
      "A value is trying to be set on a copy of a slice from a DataFrame.\n",
      "Try using .loc[row_indexer,col_indexer] = value instead\n",
      "\n",
      "See the caveats in the documentation: https://pandas.pydata.org/pandas-docs/stable/user_guide/indexing.html#returning-a-view-versus-a-copy\n",
      "\n",
      "127.0.0.1 - - [12/May/2023 16:20:59] \"POST /_dash-update-component HTTP/1.1\" 200 -\n",
      "[2023-05-12 16:20:59,145] ERROR in app: Exception on /_dash-update-component [POST]\n",
      "Traceback (most recent call last):\n",
      "  File \"C:\\Users\\DELL\\AppData\\Roaming\\Python\\Python39\\site-packages\\flask\\app.py\", line 2528, in wsgi_app\n",
      "    response = self.full_dispatch_request()\n",
      "  File \"C:\\Users\\DELL\\AppData\\Roaming\\Python\\Python39\\site-packages\\flask\\app.py\", line 1825, in full_dispatch_request\n",
      "    rv = self.handle_user_exception(e)\n",
      "  File \"C:\\Users\\DELL\\AppData\\Roaming\\Python\\Python39\\site-packages\\flask\\app.py\", line 1823, in full_dispatch_request\n",
      "    rv = self.dispatch_request()\n",
      "  File \"C:\\Users\\DELL\\AppData\\Roaming\\Python\\Python39\\site-packages\\flask\\app.py\", line 1799, in dispatch_request\n",
      "    return self.ensure_sync(self.view_functions[rule.endpoint])(**view_args)\n",
      "  File \"C:\\ProgramData\\Anaconda3\\lib\\site-packages\\dash\\dash.py\", line 1283, in dispatch\n",
      "    ctx.run(\n",
      "  File \"C:\\ProgramData\\Anaconda3\\lib\\site-packages\\dash\\_callback.py\", line 450, in add_context\n",
      "    output_value = func(*func_args, **func_kwargs)  # %% callback invoked %%\n",
      "  File \"C:\\Users\\DELL\\AppData\\Local\\Temp\\ipykernel_16068\\3660098658.py\", line 18, in get_scatter_chart\n",
      "    return px.scatter (filtered_df,\n",
      "  File \"C:\\ProgramData\\Anaconda3\\lib\\site-packages\\plotly\\express\\_chart_types.py\", line 66, in scatter\n",
      "    return make_figure(args=locals(), constructor=go.Scatter)\n",
      "  File \"C:\\ProgramData\\Anaconda3\\lib\\site-packages\\plotly\\express\\_core.py\", line 1990, in make_figure\n",
      "    args = build_dataframe(args, constructor)\n",
      "  File \"C:\\ProgramData\\Anaconda3\\lib\\site-packages\\plotly\\express\\_core.py\", line 1405, in build_dataframe\n",
      "    df_output, wide_id_vars = process_args_into_dataframe(\n",
      "  File \"C:\\ProgramData\\Anaconda3\\lib\\site-packages\\plotly\\express\\_core.py\", line 1207, in process_args_into_dataframe\n",
      "    raise ValueError(err_msg)\n",
      "ValueError: Value of 'color' is not the name of a column in 'data_frame'. Expected one of ['Unnamed: 0', 'Flight Number', 'Date', 'Time (UTC)', 'Booster Version', 'Launch Site', 'Payload', 'Payload Mass (kg)', 'Orbit', 'Customer', 'Landing Outcome', 'class', 'Lat', 'Long', 'outcome', 'counts'] but received: Booster Version Category\n",
      "127.0.0.1 - - [12/May/2023 16:20:59] \"POST /_dash-update-component HTTP/1.1\" 500 -\n",
      "C:\\Users\\DELL\\AppData\\Local\\Temp\\ipykernel_16068\\2431199016.py:10: SettingWithCopyWarning:\n",
      "\n",
      "\n",
      "A value is trying to be set on a copy of a slice from a DataFrame.\n",
      "Try using .loc[row_indexer,col_indexer] = value instead\n",
      "\n",
      "See the caveats in the documentation: https://pandas.pydata.org/pandas-docs/stable/user_guide/indexing.html#returning-a-view-versus-a-copy\n",
      "\n",
      "C:\\Users\\DELL\\AppData\\Local\\Temp\\ipykernel_16068\\2431199016.py:11: SettingWithCopyWarning:\n",
      "\n",
      "\n",
      "A value is trying to be set on a copy of a slice from a DataFrame.\n",
      "Try using .loc[row_indexer,col_indexer] = value instead\n",
      "\n",
      "See the caveats in the documentation: https://pandas.pydata.org/pandas-docs/stable/user_guide/indexing.html#returning-a-view-versus-a-copy\n",
      "\n",
      "127.0.0.1 - - [12/May/2023 16:26:05] \"POST /_dash-update-component HTTP/1.1\" 200 -\n",
      "[2023-05-12 16:26:05,699] ERROR in app: Exception on /_dash-update-component [POST]\n",
      "Traceback (most recent call last):\n",
      "  File \"C:\\Users\\DELL\\AppData\\Roaming\\Python\\Python39\\site-packages\\flask\\app.py\", line 2528, in wsgi_app\n",
      "    response = self.full_dispatch_request()\n",
      "  File \"C:\\Users\\DELL\\AppData\\Roaming\\Python\\Python39\\site-packages\\flask\\app.py\", line 1825, in full_dispatch_request\n",
      "    rv = self.handle_user_exception(e)\n",
      "  File \"C:\\Users\\DELL\\AppData\\Roaming\\Python\\Python39\\site-packages\\flask\\app.py\", line 1823, in full_dispatch_request\n",
      "    rv = self.dispatch_request()\n",
      "  File \"C:\\Users\\DELL\\AppData\\Roaming\\Python\\Python39\\site-packages\\flask\\app.py\", line 1799, in dispatch_request\n",
      "    return self.ensure_sync(self.view_functions[rule.endpoint])(**view_args)\n",
      "  File \"C:\\ProgramData\\Anaconda3\\lib\\site-packages\\dash\\dash.py\", line 1283, in dispatch\n",
      "    ctx.run(\n",
      "  File \"C:\\ProgramData\\Anaconda3\\lib\\site-packages\\dash\\_callback.py\", line 450, in add_context\n",
      "    output_value = func(*func_args, **func_kwargs)  # %% callback invoked %%\n",
      "  File \"C:\\Users\\DELL\\AppData\\Local\\Temp\\ipykernel_16068\\3660098658.py\", line 18, in get_scatter_chart\n",
      "    return px.scatter (filtered_df,\n",
      "  File \"C:\\ProgramData\\Anaconda3\\lib\\site-packages\\plotly\\express\\_chart_types.py\", line 66, in scatter\n",
      "    return make_figure(args=locals(), constructor=go.Scatter)\n",
      "  File \"C:\\ProgramData\\Anaconda3\\lib\\site-packages\\plotly\\express\\_core.py\", line 1990, in make_figure\n",
      "    args = build_dataframe(args, constructor)\n",
      "  File \"C:\\ProgramData\\Anaconda3\\lib\\site-packages\\plotly\\express\\_core.py\", line 1405, in build_dataframe\n",
      "    df_output, wide_id_vars = process_args_into_dataframe(\n",
      "  File \"C:\\ProgramData\\Anaconda3\\lib\\site-packages\\plotly\\express\\_core.py\", line 1207, in process_args_into_dataframe\n",
      "    raise ValueError(err_msg)\n",
      "ValueError: Value of 'color' is not the name of a column in 'data_frame'. Expected one of ['Unnamed: 0', 'Flight Number', 'Date', 'Time (UTC)', 'Booster Version', 'Launch Site', 'Payload', 'Payload Mass (kg)', 'Orbit', 'Customer', 'Landing Outcome', 'class', 'Lat', 'Long', 'outcome', 'counts'] but received: Booster Version Category\n"
     ]
    },
    {
     "name": "stderr",
     "output_type": "stream",
     "text": [
      "127.0.0.1 - - [12/May/2023 16:26:05] \"POST /_dash-update-component HTTP/1.1\" 500 -\n"
     ]
    }
   ],
   "source": [
    "if __name__ == '__main__':\n",
    "    app.run_server()"
   ]
  },
  {
   "cell_type": "code",
   "execution_count": null,
   "id": "4e5e85f9",
   "metadata": {},
   "outputs": [],
   "source": []
  },
  {
   "cell_type": "code",
   "execution_count": null,
   "id": "a4fe1e50",
   "metadata": {},
   "outputs": [],
   "source": []
  },
  {
   "cell_type": "code",
   "execution_count": null,
   "id": "7ff87376",
   "metadata": {},
   "outputs": [],
   "source": []
  },
  {
   "cell_type": "code",
   "execution_count": null,
   "id": "a2269cf4",
   "metadata": {},
   "outputs": [],
   "source": []
  }
 ],
 "metadata": {
  "kernelspec": {
   "display_name": "Python 3 (ipykernel)",
   "language": "python",
   "name": "python3"
  },
  "language_info": {
   "codemirror_mode": {
    "name": "ipython",
    "version": 3
   },
   "file_extension": ".py",
   "mimetype": "text/x-python",
   "name": "python",
   "nbconvert_exporter": "python",
   "pygments_lexer": "ipython3",
   "version": "3.9.13"
  }
 },
 "nbformat": 4,
 "nbformat_minor": 5
}
